Workbook
Name tbl_MC: MC_SIM_OUT!$A$1:$E$31

Sheet Cover
B2: Carbon Pricing Exposure & Firm Valuation Model
B4: Paulian Oprescu

Sheet MC_SIM_OUT
A1: Year | B1: P25 | C1: P50 | D1: P75 | E1: Regime
A2: 2026 | B2: 70.37 | C2: 70.37 | D2: 70.37 | E2: status_quo
A3: 2027 | B3: 59.34 | C3: 70.26 | D3: 83.17 | E3: status_quo
A4: 2028 | B4: 55.26 | C4: 70.15 | D4: 89.09 | E4: status_quo
A5: 2029 | B5: 52.31 | C5: 70.02 | D5: 93.9 | E5: status_quo
A6: 2030 | B6: 49.95 | C6: 70 | D6: 98.05 | E6: status_quo
A7: 2031 | B7: 47.95 | C7: 69.97 | D7: 101.94 | E7: status_quo
A8: 2032 | B8: 46.18 | C8: 69.82 | D8: 105.48 | E8: status_quo
A9: 2033 | B9: 44.65 | C9: 69.7 | D9: 109.05 | E9: status_quo
A10: 2034 | B10: 43.27 | C10: 69.62 | D10: 112.26 | E10: status_quo
A11: 2035 | B11: 41.96 | C11: 69.57 | D11: 115.53 | E11: status_quo
A12: 2026 | B12: 70.37 | C12: 70.37 | D12: 70.37 | E12: fit_for_55
A13: 2027 | B13: 61.19 | C13: 72.43 | D13: 85.7 | E13: fit_for_55
... A31: 2035 | B31: 78.73 | C31: 130.53 | D31: 216.54 | E31: accelerated

Sheet Assumptions
B2: Assumptions
B4: CAPM & WACC | E4: Market Index | G4: Risk-Free Rate | I4: Market Risk Premium
B6: Symbol | E6: rM | G6: rF | I6: ErM - rF
B7: Value | E7: 0.0102 | G7: 0.02822 | I7: 0.055
B8: Variable Name | E8: STOXX Europe 600 ϐ | G8: German Bund (10y) Yield | I8: European Practice Return Rate
B10: Δ Carbon Emission & Exposure | E10: Reported tCO2e | G10: EBITDA ($) | I10: Intensity (t CO2 / $ ) | K10: iCO2 | M10: g | O10: ϑ
B12: Novartis AG | E12: 200400 | G12: 24923000000 | I12: =$E12/$G12 -> 8.0407656e-06 | K12: =GEOMEAN(I12:I15) -> 1.0207209e-05 | M12: =0.25*DataSources!M7+ 0.25*DataSources!M8 + 0.5*DataSources!M9 -> -0.0021938515 | O12: 0.4
B13: UCB SA | E13: 16291 | G13: 1852000000 | I13: =$E13/$G13 -> 8.7964363e-06
B14: Johnson & Johnson | E14: 460864 | G14: 31922000000 | I14: =$E14/$G14 -> 1.4437191e-05
B15: AstraZeneca | E15: 217026 | G15: 20416000000 | I15: =$E15/$G15 -> 1.0630192e-05
B18: Logista | E18: 12159 | G18: 402974000 | I18: =$E18/$G18 -> 3.0173163e-05 | K18: =GEOMEAN(I18:I20) -> 4.527201e-05 | M18: =0.25*DataSources!M7 + 0.25*DataSources!M8 + 0.25*DataSources!M10 + 0.25*DataSources!M11 -> 0.0088259464 | O18: 0.7
B19: C.H. Robinson | E19: 32339 | G19: 871163000 | I19: =$E19/$G19 -> 3.7121641e-05
B20: Kuehne + Nagel | E20: 140000 | G20: 1690000000 | I20: =$E20/$G20 -> 8.2840237e-05
B24: Iberdrola | E24: 24000000 | G24: 15985000000 | I24: =$E24/$G24 -> 0.0015014076 | K24: =GEOMEAN(I24:I27) -> 0.0011895828 | M24: =0.25*DataSources!M7 + 0.25*DataSources!M8 + 0.25*DataSources!M12 + 0.25*DataSources!M13 -> 0.0031823119 | O24: 1
B25: Shell | E25: 49000000 | G25: 48755000000 | I25: =$E25/$G25 -> 0.0010050251
B26: TotalEnergies SE | E26: 32000000 | G26: 35641000000 | I26: =$E26/$G26 -> 0.00089784237
B27: Engie | E27: 22000000 | G27: 14884000000 | I27: =$E27/$G27 -> 0.0014780973
B29: SBTI Compliance | E29: 2x Target Set | G29: 1x Target Set & Committed/None | I29: None
B31: DeCarbonisation Rate p.a. | E31: 0.035 | G31: 0.015 | I31: 0

Sheet ControlPanel
B2: EU Carbon Policy Regime
B6: Policy Regime : | C6: accelerated | XFB6: status_quo | XFC6: fit_for_55 | XFD6: accelerated
B7: Price Percentile : | C7: P75 | XFB7: P25 | XFC7: P50 | XFD7: P75
B9: Year | C9: Price
B10: {=_xlfn._xlws.SORT(_xlfn.UNIQUE(_xlfn._xlws.FILTER(MC_SIM_OUT!A2:A31, MC_SIM_OUT!E2:E31=$C$6)))} -> 2026 | C10: {=_xlfn.SORTBY(_xlfn._xlws.FILTER(CHOOSE(MATCH($C$7, {"P25";"P50";"P75"}, 0), MC_SIM_OUT!B2:B31, MC_SIM_OUT!C2:C31, MC_SIM_OUT!D2:D31), MC_SIM_OUT!E2:E31=$C$6), _xlfn._xlws.FILTER(MC_SIM_OUT!A2:A31, MC_SIM_OUT!E2:E31=$C$6),1)} -> 70.37
B11: 2027 | C11: 89.25
B12: 2028 | C12: 102.46
B13: 2029 | C13: 115.9
B14: 2030 | C14: 129.8
B15: 2031 | C15: 144.67
B16: 2032 | C16: 160.68
B17: 2033 | C17: 177.87
B18: 2034 | C18: 196.45
B19: 2035 | C19: 216.54

Sheet Carbon_Emission&Exposure
B2: Carbon Emission & Exposure
B5: Emissions | C5: EBITDA ($) | D5: E0 | E5: SBTId | G5: 2026 | H5: =G5+1 -> 2027 | I5: =H5+1 -> 2028 | J5: =I5+1 -> 2029 | K5: =J5+1 -> 2030 | L5: =K5+1 -> 2031 | M5: =L5+1 -> 2032 | N5: =M5+1 -> 2033 | O5: =N5+1 -> 2034 | P5: =O5+1 -> 2035
B7: LIFE SCIENCES
B9: AstraZeneca PLC | C9: 20416000000 | D9: =$C9*Assumptions!$K$12 -> 208390.37 | E9: =Assumptions!$E$31 -> 0.035 | G9: =$D9*((1-$E9)*(1+Assumptions!$M$12))^1 -> 200655.53 | H9: =$D9*((1-$E9)*(1+Assumptions!$M$12))^2 -> 193207.79 | I9: =$D9*((1-$E9)*(1+Assumptions!$M$12))^3 -> 186036.48 | J9: =$D9*((1-$E9)*(1+Assumptions!$M$12))^4 -> 179131.35 | K9: =$D9*((1-$E9)*(1+Assumptions!$M$12))^5 -> 172482.52 | L9: =$D9*((1-$E9)*(1+Assumptions!$M$12))^6 -> 166080.48 | M9: =$D9*((1-$E9)*(1+Assumptions!$M$12))^7 -> 159916.06 | N9: =$D9*((1-$E9)*(1+Assumptions!$M$12))^8 -> 153980.44 | O9: =$D9*((1-$E9)*(1+Assumptions!$M$12))^9 -> 148265.14 | P9: =$D9*((1-$E9)*(1+Assumptions!$M$12))^10 -> 142761.97
B10: Bayer AG | C10: 8084000000 | D10: =$C10*Assumptions!$K$12 -> 82515.074 | E10: =Assumptions!$E$31 -> 0.035 | G10: =$D10*((1-$E10)*(1+Assumptions!$M$12))^1 -> 79452.357 | H10: =$D10*((1-$E10)*(1+Assumptions!$M$12))^2 -> 76503.318 | I10: =$D10*((1-$E10)*(1+Assumptions!$M$12))^3 -> 73663.74 | J10: =$D10*((1-$E10)*(1+Assumptions!$M$12))^4 -> 70929.558 | K10: =$D10*((1-$E10)*(1+Assumptions!$M$12))^5 -> 68296.861 | L10: =$D10*((1-$E10)*(1+Assumptions!$M$12))^6 -> 65761.881 | M10: =$D10*((1-$E10)*(1+Assumptions!$M$12))^7 -> 63320.993 | N10: =$D10*((1-$E10)*(1+Assumptions!$M$12))^8 -> 60970.704 | O10: =$D10*((1-$E10)*(1+Assumptions!$M$12))^9 -> 58707.65 | P10: =$D10*((1-$E10)*(1+Assumptions!$M$12))^10 -> 56528.594
B11: Novartis AG | C11: 24923000000 | D11: =$C11*Assumptions!$K$12 -> 254394.26 | E11: =Assumptions!$E$31 -> 0.035 | G11: =$D11*((1-$E11)*(1+Assumptions!$M$12))^1 -> 244951.89 | H11: =$D11*((1-$E11)*(1+Assumptions!$M$12))^2 -> 235860 | I11: =$D11*((1-$E11)*(1+Assumptions!$M$12))^3 -> 227105.56 | J11: =$D11*((1-$E11)*(1+Assumptions!$M$12))^4 -> 218676.07 | K11: =$D11*((1-$E11)*(1+Assumptions!$M$12))^5 -> 210559.46 | L11: =$D11*((1-$E11)*(1+Assumptions!$M$12))^6 -> 202744.11 | M11: =$D11*((1-$E11)*(1+Assumptions!$M$12))^7 -> 195218.84 | N11: =$D11*((1-$E11)*(1+Assumptions!$M$12))^8 -> 187972.89 | O11: =$D11*((1-$E11)*(1+Assumptions!$M$12))^9 -> 180995.89 | P11: =$D11*((1-$E11)*(1+Assumptions!$M$12))^10 -> 174277.85
B12: Roche Holding AG | C12: 23429000000 | D12: =$C12*Assumptions!$K$12 -> 239144.69 | E12: =Assumptions!$E$31 -> 0.035 | G12: =$D12*((1-$E12)*(1+Assumptions!$M$12))^1 -> 230268.34 | H12: =$D12*((1-$E12)*(1+Assumptions!$M$12))^2 -> 221721.46 | I12: =$D12*((1-$E12)*(1+Assumptions!$M$12))^3 -> 213491.81 | J12: =$D12*((1-$E12)*(1+Assumptions!$M$12))^4 -> 205567.62 | K12: =$D12*((1-$E12)*(1+Assumptions!$M$12))^5 -> 197937.55 | L12: =$D12*((1-$E12)*(1+Assumptions!$M$12))^6 -> 190590.69 | M12: =$D12*((1-$E12)*(1+Assumptions!$M$12))^7 -> 183516.52 | N12: =$D12*((1-$E12)*(1+Assumptions!$M$12))^8 -> 176704.93 | O12: =$D12*((1-$E12)*(1+Assumptions!$M$12))^9 -> 170146.16 | P12: =$D12*((1-$E12)*(1+Assumptions!$M$12))^10 -> 163830.83
B13: Sanofi | C13: 12334000000 | D13: =$C13*Assumptions!$K$12 -> 125895.71 | E13: =Assumptions!$E$31 -> 0.035 | G13: =$D13*((1-$E13)*(1+Assumptions!$M$12))^1 -> 121222.83 | H13: =$D13*((1-$E13)*(1+Assumptions!$M$12))^2 -> 116723.4 | I13: =$D13*((1-$E13)*(1+Assumptions!$M$12))^3 -> 112390.97 | J13: =$D13*((1-$E13)*(1+Assumptions!$M$12))^4 -> 108219.34 | K13: =$D13*((1-$E13)*(1+Assumptions!$M$12))^5 -> 104202.56 | L13: =$D13*((1-$E13)*(1+Assumptions!$M$12))^6 -> 100334.86 | M13: =$D13*((1-$E13)*(1+Assumptions!$M$12))^7 -> 96610.729 | N13: =$D13*((1-$E13)*(1+Assumptions!$M$12))^8 -> 93024.822 | O13: =$D13*((1-$E13)*(1+Assumptions!$M$12))^9 -> 89572.013 | P13: =$D13*((1-$E13)*(1+Assumptions!$M$12))^10 -> 86247.363
B14: UCB SA | C14: 1852000000 | D14: =$C14*Assumptions!$K$12 -> 18903.75 | E14: =Assumptions!$E$31 -> 0.035 | G14: =$D14*((1-$E14)*(1+Assumptions!$M$12))^1 -> 18202.099 | H14: =$D14*((1-$E14)*(1+Assumptions!$M$12))^2 -> 17526.49 | I14: =$D14*((1-$E14)*(1+Assumptions!$M$12))^3 -> 16875.958 | J14: =$D14*((1-$E14)*(1+Assumptions!$M$12))^4 -> 16249.572 | K14: =$D14*((1-$E14)*(1+Assumptions!$M$12))^5 -> 15646.436 | L14: =$D14*((1-$E14)*(1+Assumptions!$M$12))^6 -> 15065.686 | M14: =$D14*((1-$E14)*(1+Assumptions!$M$12))^7 -> 14506.492 | N14: =$D14*((1-$E14)*(1+Assumptions!$M$12))^8 -> 13968.053 | O14: =$D14*((1-$E14)*(1+Assumptions!$M$12))^9 -> 13449.6 | P14: =$D14*((1-$E14)*(1+Assumptions!$M$12))^10 -> 12950.39
B15: GSK plc | C15: 9519000000 | D15: =$C15*Assumptions!$K$12 -> 97162.419 | E15: =Assumptions!$E$31 -> 0.035 | G15: =$D15*((1-$E15)*(1+Assumptions!$M$12))^1 -> 93556.035 | H15: =$D15*((1-$E15)*(1+Assumptions!$M$12))^2 -> 90083.509 | I15: =$D15*((1-$E15)*(1+Assumptions!$M$12))^3 -> 86739.874 | J15: =$D15*((1-$E15)*(1+Assumptions!$M$12))^4 -> 83520.344 | K15: =$D15*((1-$E15)*(1+Assumptions!$M$12))^5 -> 80420.314 | L15: =$D15*((1-$E15)*(1+Assumptions!$M$12))^6 -> 77435.348 | M15: =$D15*((1-$E15)*(1+Assumptions!$M$12))^7 -> 74561.175 | N15: =$D15*((1-$E15)*(1+Assumptions!$M$12))^8 -> 71793.682 | O15: =$D15*((1-$E15)*(1+Assumptions!$M$12))^9 -> 69128.912 | P15: =$D15*((1-$E15)*(1+Assumptions!$M$12))^10 -> 66563.049
B16: BioNTech SE | C16: 467800000 | D16: =$C16*Assumptions!$K$12 -> 4774.9322 | E16: =Assumptions!$G$31 -> 0.015 | G16: =$D16*((1-$E16)*(1+Assumptions!$M$12))^1 -> 4692.9898 | H16: =$D16*((1-$E16)*(1+Assumptions!$M$12))^2 -> 4612.4537 | I16: =$D16*((1-$E16)*(1+Assumptions!$M$12))^3 -> 4533.2996 | J16: =$D16*((1-$E16)*(1+Assumptions!$M$12))^4 -> 4455.5039 | K16: =$D16*((1-$E16)*(1+Assumptions!$M$12))^5 -> 4379.0433 | L16: =$D16*((1-$E16)*(1+Assumptions!$M$12))^6 -> 4303.8948 | M16: =$D16*((1-$E16)*(1+Assumptions!$M$12))^7 -> 4230.0359 | N16: =$D16*((1-$E16)*(1+Assumptions!$M$12))^8 -> 4157.4445 | O16: =$D16*((1-$E16)*(1+Assumptions!$M$12))^9 -> 4086.0988 | P16: =$D16*((1-$E16)*(1+Assumptions!$M$12))^10 -> 4015.9775
B17: Pfizer | C17: 24459000000 | D17: =$C17*Assumptions!$K$12 -> 249658.12 | E17: =Assumptions!$G$31 -> 0.015 | G17: =$D17*((1-$E17)*(1+Assumptions!$M$12))^1 -> 245373.75 | H17: =$D17*((1-$E17)*(1+Assumptions!$M$12))^2 -> 241162.9 | I17: =$D17*((1-$E17)*(1+Assumptions!$M$12))^3 -> 237024.32 | J17: =$D17*((1-$E17)*(1+Assumptions!$M$12))^4 -> 232956.76 | K17: =$D17*((1-$E17)*(1+Assumptions!$M$12))^5 -> 228959 | L17: =$D17*((1-$E17)*(1+Assumptions!$M$12))^6 -> 225029.85 | M17: =$D17*((1-$E17)*(1+Assumptions!$M$12))^7 -> 221168.12 | N17: =$D17*((1-$E17)*(1+Assumptions!$M$12))^8 -> 217372.67 | O17: =$D17*((1-$E17)*(1+Assumptions!$M$12))^9 -> 213642.35 | P17: =$D17*((1-$E17)*(1+Assumptions!$M$12))^10 -> 209976.04
B18: Johnson & Johnson | C18: 31922000000 | D18: =$C18*Assumptions!$K$12 -> 325834.51 | E18: =Assumptions!$G$31 -> 0.015 | G18: =$D18*((1-$E18)*(1+Assumptions!$M$12))^1 -> 320242.89 | H18: =$D18*((1-$E18)*(1+Assumptions!$M$12))^2 -> 314747.22 | I18: =$D18*((1-$E18)*(1+Assumptions!$M$12))^3 -> 309345.86 | J18: =$D18*((1-$E18)*(1+Assumptions!$M$12))^4 -> 304037.19 | K18: =$D18*((1-$E18)*(1+Assumptions!$M$12))^5 -> 298819.62 | L18: =$D18*((1-$E18)*(1+Assumptions!$M$12))^6 -> 293691.6 | M18: =$D18*((1-$E18)*(1+Assumptions!$M$12))^7 -> 288651.57 | N18: =$D18*((1-$E18)*(1+Assumptions!$M$12))^8 -> 283698.04 | O18: =$D18*((1-$E18)*(1+Assumptions!$M$12))^9 -> 278829.51 | P18: =$D18*((1-$E18)*(1+Assumptions!$M$12))^10 -> 274044.54
B21: Transport
B24: PostNL | C24: 125000000 | D24: =$C24*Assumptions!$K$18 -> 5659.0012 | E24: =Assumptions!$E$31 -> 0.035 | G24: =$D24*((1-$E24)*(1+Assumptions!$M$18))^1 -> 5509.1341 | H24: =$D24*((1-$E24)*(1+Assumptions!$M$18))^2 -> 5363.2359 | I24: =$D24*((1-$E24)*(1+Assumptions!$M$18))^3 -> 5221.2016 | J24: =$D24*((1-$E24)*(1+Assumptions!$M$18))^4 -> 5082.9287 | K24: =$D24*((1-$E24)*(1+Assumptions!$M$18))^5 -> 4948.3177 | L24: =$D24*((1-$E24)*(1+Assumptions!$M$18))^6 -> 4817.2716 | M24: =$D24*((1-$E24)*(1+Assumptions!$M$18))^7 -> 4689.696 | N24: =$D24*((1-$E24)*(1+Assumptions!$M$18))^8 -> 4565.4989 | O24: =$D24*((1-$E24)*(1+Assumptions!$M$18))^9 -> 4444.591 | P24: =$D24*((1-$E24)*(1+Assumptions!$M$18))^10 -> 4326.885
B25: DHL Group | C25: 7925000000 | D25: =$C25*Assumptions!$K$18 -> 358780.68 | E25: =Assumptions!$E$31 -> 0.035 | G25: =$D25*((1-$E25)*(1+Assumptions!$M$18))^1 -> 349279.1 | H25: =$D25*((1-$E25)*(1+Assumptions!$M$18))^2 -> 340029.16 | I25: =$D25*((1-$E25)*(1+Assumptions!$M$18))^3 -> 331024.18 | J25: =$D25*((1-$E25)*(1+Assumptions!$M$18))^4 -> 322257.68 | K25: =$D25*((1-$E25)*(1+Assumptions!$M$18))^5 -> 313723.34 | L25: =$D25*((1-$E25)*(1+Assumptions!$M$18))^6 -> 305415.02 | M25: =$D25*((1-$E25)*(1+Assumptions!$M$18))^7 -> 297326.72 | N25: =$D25*((1-$E25)*(1+Assumptions!$M$18))^8 -> 289452.63 | O25: =$D25*((1-$E25)*(1+Assumptions!$M$18))^9 -> 281787.07 | P25: =$D25*((1-$E25)*(1+Assumptions!$M$18))^10 -> 274324.51
B26: XPO Logistics | C26: 1244000000 | D26: =$C26*Assumptions!$K$18 -> 56318.38 | E26: =Assumptions!$G$31 -> 0.015 | G26: =$D26*((1-$E26)*(1+Assumptions!$M$18))^1 -> 55963.212 | H26: =$D26*((1-$E26)*(1+Assumptions!$M$18))^2 -> 55610.283 | I26: =$D26*((1-$E26)*(1+Assumptions!$M$18))^3 -> 55259.58 | J26: =$D26*((1-$E26)*(1+Assumptions!$M$18))^4 -> 54911.088 | K26: =$D26*((1-$E26)*(1+Assumptions!$M$18))^5 -> 54564.795 | L26: =$D26*((1-$E26)*(1+Assumptions!$M$18))^6 -> 54220.685 | M26: =$D26*((1-$E26)*(1+Assumptions!$M$18))^7 -> 53878.745 | N26: =$D26*((1-$E26)*(1+Assumptions!$M$18))^8 -> 53538.962 | O26: =$D26*((1-$E26)*(1+Assumptions!$M$18))^9 -> 53201.322 | P26: =$D26*((1-$E26)*(1+Assumptions!$M$18))^10 -> 52865.811
B27: Logista | C27: 402974000 | D27: =$C27*Assumptions!$K$18 -> 18243.443 | E27: =Assumptions!$G$31 -> 0.015 | G27: =$D27*((1-$E27)*(1+Assumptions!$M$18))^1 -> 18128.392 | H27: =$D27*((1-$E27)*(1+Assumptions!$M$18))^2 -> 18014.066 | I27: =$D27*((1-$E27)*(1+Assumptions!$M$18))^3 -> 17900.461 | J27: =$D27*((1-$E27)*(1+Assumptions!$M$18))^4 -> 17787.573 | K27: =$D27*((1-$E27)*(1+Assumptions!$M$18))^5 -> 17675.397 | L27: =$D27*((1-$E27)*(1+Assumptions!$M$18))^6 -> 17563.928 | M27: =$D27*((1-$E27)*(1+Assumptions!$M$18))^7 -> 17453.162 | N27: =$D27*((1-$E27)*(1+Assumptions!$M$18))^8 -> 17343.095 | O27: =$D27*((1-$E27)*(1+Assumptions!$M$18))^9 -> 17233.721 | P27: =$D27*((1-$E27)*(1+Assumptions!$M$18))^10 -> 17125.038
B28: Kuehne + Nagel | C28: 1690000000 | D28: =$C28*Assumptions!$K$18 -> 76509.697 | E28: =Assumptions!$G$31 -> 0.015 | G28: =$D28*((1-$E28)*(1+Assumptions!$M$18))^1 -> 76027.193 | H28: =$D28*((1-$E28)*(1+Assumptions!$M$18))^2 -> 75547.732 | I28: =$D28*((1-$E28)*(1+Assumptions!$M$18))^3 -> 75071.294 | J28: =$D28*((1-$E28)*(1+Assumptions!$M$18))^4 -> 74597.861 | K28: =$D28*((1-$E28)*(1+Assumptions!$M$18))^5 -> 74127.414 | L28: =$D28*((1-$E28)*(1+Assumptions!$M$18))^6 -> 73659.934 | M28: =$D28*((1-$E28)*(1+Assumptions!$M$18))^7 -> 73195.402 | N28: =$D28*((1-$E28)*(1+Assumptions!$M$18))^8 -> 72733.799 | O28: =$D28*((1-$E28)*(1+Assumptions!$M$18))^9 -> 72275.108 | P28: =$D28*((1-$E28)*(1+Assumptions!$M$18))^10 -> 71819.309
B29: C.H. Robinson | C29: 871163000 | D29: =$C29*Assumptions!$K$18 -> 39439.3 | E29: =Assumptions!$I$31 -> 0 | G29: =$D29*((1-$E29)*(1+Assumptions!$M$18))^1 -> 39787.389 | H29: =$D29*((1-$E29)*(1+Assumptions!$M$18))^2 -> 40138.55 | I29: =$D29*((1-$E29)*(1+Assumptions!$M$18))^3 -> 40492.811 | J29: =$D29*((1-$E29)*(1+Assumptions!$M$18))^4 -> 40850.199 | K29: =$D29*((1-$E29)*(1+Assumptions!$M$18))^5 -> 41210.74 | L29: =$D29*((1-$E29)*(1+Assumptions!$M$18))^6 -> 41574.464 | M29: =$D29*((1-$E29)*(1+Assumptions!$M$18))^7 -> 41941.398 | N29: =$D29*((1-$E29)*(1+Assumptions!$M$18))^8 -> 42311.571 | O29: =$D29*((1-$E29)*(1+Assumptions!$M$18))^9 -> 42685.01 | P29: =$D29*((1-$E29)*(1+Assumptions!$M$18))^10 -> 43061.746
B31: Energy
B33: Iberdrola | C33: 15985000000 | D33: =$C33*Assumptions!$K$24 -> 19015480 | E33: =Assumptions!$E$31 -> 0.035 | G33: =$D33*((1-$E33)*(1+Assumptions!$M$24))^1 -> 18408334 | H33: =$D33*((1-$E33)*(1+Assumptions!$M$24))^2 -> 17820573 | I33: =$D33*((1-$E33)*(1+Assumptions!$M$24))^3 -> 17251578 | J33: =$D33*((1-$E33)*(1+Assumptions!$M$24))^4 -> 16700752 | K33: =$D33*((1-$E33)*(1+Assumptions!$M$24))^5 -> 16167512 | L33: =$D33*((1-$E33)*(1+Assumptions!$M$24))^6 -> 15651299 | M33: =$D33*((1-$E33)*(1+Assumptions!$M$24))^7 -> 15151567 | N33: =$D33*((1-$E33)*(1+Assumptions!$M$24))^8 -> 14667792 | O33: =$D33*((1-$E33)*(1+Assumptions!$M$24))^9 -> 14199463 | P33: =$D33*((1-$E33)*(1+Assumptions!$M$24))^10 -> 13746087
B34: Elia | C34: 1912000000 | D34: =$C34*Assumptions!$K$24 -> 2274482.2 | E34: =Assumptions!$E$31 -> 0.035 | G34: =$D34*((1-$E34)*(1+Assumptions!$M$24))^1 -> 2201860.1 | H34: =$D34*((1-$E34)*(1+Assumptions!$M$24))^2 -> 2131556.8 | I34: =$D34*((1-$E34)*(1+Assumptions!$M$24))^3 -> 2063498.2 | J34: =$D34*((1-$E34)*(1+Assumptions!$M$24))^4 -> 1997612.6 | K34: =$D34*((1-$E34)*(1+Assumptions!$M$24))^5 -> 1933830.7 | L34: =$D34*((1-$E34)*(1+Assumptions!$M$24))^6 -> 1872085.3 | M34: =$D34*((1-$E34)*(1+Assumptions!$M$24))^7 -> 1812311.3 | N34: =$D34*((1-$E34)*(1+Assumptions!$M$24))^8 -> 1754445.9 | O34: =$D34*((1-$E34)*(1+Assumptions!$M$24))^9 -> 1698428.1 | P34: =$D34*((1-$E34)*(1+Assumptions!$M$24))^10 -> 1644198.9
B35: Engie | C35: 14884000000 | D35: =$C35*Assumptions!$K$24 -> 17705750 | E35: =Assumptions!$G$31 -> 0.015 | G35: =$D35*((1-$E35)*(1+Assumptions!$M$24))^1 -> 17495664 | H35: =$D35*((1-$E35)*(1+Assumptions!$M$24))^2 -> 17288070 | I35: =$D35*((1-$E35)*(1+Assumptions!$M$24))^3 -> 17082940 | J35: =$D35*((1-$E35)*(1+Assumptions!$M$24))^4 -> 16880243 | K35: =$D35*((1-$E35)*(1+Assumptions!$M$24))^5 -> 16679952 | L35: =$D35*((1-$E35)*(1+Assumptions!$M$24))^6 -> 16482038 | M35: =$D35*((1-$E35)*(1+Assumptions!$M$24))^7 -> 16286471 | N35: =$D35*((1-$E35)*(1+Assumptions!$M$24))^8 -> 16093225 | O35: =$D35*((1-$E35)*(1+Assumptions!$M$24))^9 -> 15902272 | P35: =$D35*((1-$E35)*(1+Assumptions!$M$24))^10 -> 15713585
B36: TotalEnergies SE | C36: 35641000000 | D36: =$C36*Assumptions!$K$24 -> 42397919 | E36: =Assumptions!$I$31 -> 0 | G36: =$D36*((1-$E36)*(1+Assumptions!$M$24))^1 -> 42532842 | H36: =$D36*((1-$E36)*(1+Assumptions!$M$24))^2 -> 42668195 | I36: =$D36*((1-$E36)*(1+Assumptions!$M$24))^3 -> 42803979 | J36: =$D36*((1-$E36)*(1+Assumptions!$M$24))^4 -> 42940194 | K36: =$D36*((1-$E36)*(1+Assumptions!$M$24))^5 -> 43076843 | L36: =$D36*((1-$E36)*(1+Assumptions!$M$24))^6 -> 43213927 | M36: =$D36*((1-$E36)*(1+Assumptions!$M$24))^7 -> 43351447 | N36: =$D36*((1-$E36)*(1+Assumptions!$M$24))^8 -> 43489405 | O36: =$D36*((1-$E36)*(1+Assumptions!$M$24))^9 -> 43627802 | P36: =$D36*((1-$E36)*(1+Assumptions!$M$24))^10 -> 43766639
B37: Orsted | C37: 21156000000 | D37: =$C37*Assumptions!$K$24 -> 25166813 | E37: =Assumptions!$E$31 -> 0.035 | G37: =$D37*((1-$E37)*(1+Assumptions!$M$24))^1 -> 24363260 | H37: =$D37*((1-$E37)*(1+Assumptions!$M$24))^2 -> 23585364 | I37: =$D37*((1-$E37)*(1+Assumptions!$M$24))^3 -> 22832305 | J37: =$D37*((1-$E37)*(1+Assumptions!$M$24))^4 -> 22103291 | K37: =$D37*((1-$E37)*(1+Assumptions!$M$24))^5 -> 21397553 | L37: =$D37*((1-$E37)*(1+Assumptions!$M$24))^6 -> 20714349 | M37: =$D37*((1-$E37)*(1+Assumptions!$M$24))^7 -> 20052959 | N37: =$D37*((1-$E37)*(1+Assumptions!$M$24))^8 -> 19412687 | O37: =$D37*((1-$E37)*(1+Assumptions!$M$24))^9 -> 18792858 | P37: =$D37*((1-$E37)*(1+Assumptions!$M$24))^10 -> 18192820
B38: Shell plc | C38: 48755000000 | D38: =$C38*Assumptions!$K$24 -> 57998107 | E38: =Assumptions!$I$31 -> 0 | G38: =$D38*((1-$E38)*(1+Assumptions!$M$24))^1 -> 58182675 | H38: =$D38*((1-$E38)*(1+Assumptions!$M$24))^2 -> 58367831 | I38: =$D38*((1-$E38)*(1+Assumptions!$M$24))^3 -> 58553575 | J38: =$D38*((1-$E38)*(1+Assumptions!$M$24))^4 -> 58739911 | K38: =$D38*((1-$E38)*(1+Assumptions!$M$24))^5 -> 58926840 | L38: =$D38*((1-$E38)*(1+Assumptions!$M$24))^6 -> 59114363 | M38: =$D38*((1-$E38)*(1+Assumptions!$M$24))^7 -> 59302484 | N38: =$D38*((1-$E38)*(1+Assumptions!$M$24))^8 -> 59491203 | O38: =$D38*((1-$E38)*(1+Assumptions!$M$24))^9 -> 59680522 | P38: =$D38*((1-$E38)*(1+Assumptions!$M$24))^10 -> 59870444

Sheet DCF
J1: 100
B2: DCF
B5: Discount Rate | C5: Ticker | D5: EcoVadis | E5: ϐ | F5: rE | G5: Interest Expense | H5: Total Debt | I5: rD | J5: Tax (HQ-specific) | K5: rD (after-tax) | L5: Market Cap | M5: wE | N5: wD | O5: Discount Rate | Q5: Yearly Discount Factor | R5: 2026 | S5: =R5+1 -> 2027 | T5: =S5+1 -> 2028 | U5: =T5+1 -> 2029 | V5: =U5+1 -> 2030 | W5: =V5+1 -> 2031 | X5: =W5+1 -> 2032 | Y5: =X5+1 -> 2033 | Z5: =Y5+1 -> 2034 | AA5: =Z5+1 -> 2035
B7: LIFE SCIENCES
B9: AstraZeneca PLC | C9: AZN | D9: Gold | E9: 0.19 | F9: =Assumptions!$G$7+Assumptions!$I$7*DCF!$E9 -> 0.03867 | G9: 1682000 | H9: 30114000 | I9: =$G9/$H9 -> 0.05585442 | J9: 0.25 | K9: =$I9*(1-$J9) -> 0.041890815 | L9: 293170000000 | M9: =$L9/($L9+$H9) -> 0.99989729 | N9: =$H9/($H9+$L9) -> 0.00010270801 | O9: =$F9*$M9+$I9*$N9 -> 0.038671765 | R9: =1/(1+$O9)^1 -> 0.96276806 | S9: =1/(1+$O9)^2 -> 0.92692234 | T9: =1/(1+$O9)^3 -> 0.89241122 | U9: =1/(1+$O9)^4 -> 0.85918502 | V9: =1/(1+$O9)^5 -> 0.82719589 | W9: =1/(1+$O9)^6 -> 0.79639779 | X9: =1/(1+$O9)^7 -> 0.76674635 | Y9: =1/(1+$O9)^8 -> 0.7381989 | Z9: =1/(1+$O9)^9 -> 0.71071432 | AA9: =1/(1+$O9)^10 -> 0.68425305
B10: Bayer AG | C10: BAYN.DE | D10: Gold | E10: 0.89 | F10: =Assumptions!$G$7+Assumptions!$I$7*DCF!$E10 -> 0.07717 | G10: 2358000 | H10: 40697000 | I10: =$G10/$H10 -> 0.057940389 | J10: 0.3006 | K10: =$I10*(1-$J10) -> 0.040523508 | L10: 38200000000 | M10: =$L10/($L10+$H10) -> 0.99893577 | N10: =$H10/($H10+$L10) -> 0.0010642327 | O10: =$F10*$M10+$I10*$N10 -> 0.077149535 | R10: =1/(1+$O10)^1 -> 0.92837621 | S10: =1/(1+$O10)^2 -> 0.86188238 | T10: =1/(1+$O10)^3 -> 0.8001511 | U10: =1/(1+$O10)^4 -> 0.74284124 | V10: =1/(1+$O10)^5 -> 0.68963613 | W10: =1/(1+$O10)^6 -> 0.64024178 | X10: =1/(1+$O10)^7 -> 0.59438523 | Y10: =1/(1+$O10)^8 -> 0.55181311 | Z10: =1/(1+$O10)^9 -> 0.51229016 | AA10: =1/(1+$O10)^10 -> 0.475598
B11: Novartis AG | C11: NVS | D11: Silver | E11: 0.45 | F11: =Assumptions!$G$7+Assumptions!$I$7*DCF!$E11 -> 0.05297 | G11: 1006000 | H11: 31258000 | I11: =$G11/$H11 -> 0.032183761 | J11: 0.1961 | K11: =$I11*(1-$J11) -> 0.025872525 | L11: 272470000000 | M11: =$L11/($L11+$H11) -> 0.99988529 | N11: =$H11/($H11+$L11) -> 0.00011470773 | O11: =$F11*$M11+$I11*$N11 -> 0.052967616 | R11: =1/(1+$O11)^1 -> 0.94969682 | S11: =1/(1+$O11)^2 -> 0.90192406 | T11: =1/(1+$O11)^3 -> 0.85655441 | U11: =1/(1+$O11)^4 -> 0.813467 | V11: =1/(1+$O11)^5 -> 0.77254703 | W11: =1/(1+$O11)^6 -> 0.73368546 | X11: =1/(1+$O11)^7 -> 0.69677875 | Y11: =1/(1+$O11)^8 -> 0.66172857 | Z11: =1/(1+$O11)^9 -> 0.62844152 | AA11: =1/(1+$O11)^10 -> 0.59682891
B12: Roche Holding AG | C12: RHHVF | D12: Silver | E12: 0.17 | F12: =Assumptions!$G$7+Assumptions!$I$7*DCF!$E12 -> 0.03757 | G12: 1403000 | H12: 36354000 | I12: =$G12/$H12 -> 0.038592727 | J12: 0.1961 | K12: =$I12*(1-$J12) -> 0.031024693 | L12: 341200000000 | M12: =$L12/($L12+$H12) -> 0.99989346 | N12: =$H12/($H12+$L12) -> 0.00010653613 | O12: =$F12*$M12+$I12*$N12 -> 0.037570109 | R12: =1/(1+$O12)^1 -> 0.96379029 | S12: =1/(1+$O12)^2 -> 0.92889173 | T12: =1/(1+$O12)^3 -> 0.89525683 | U12: =1/(1+$O12)^4 -> 0.86283985 | V12: =1/(1+$O12)^5 -> 0.83159667 | W12: =1/(1+$O12)^6 -> 0.8014848 | X12: =1/(1+$O12)^7 -> 0.77246327 | Y12: =1/(1+$O12)^8 -> 0.7444926 | Z12: =1/(1+$O12)^9 -> 0.71753474 | AA12: =1/(1+$O12)^10 -> 0.69155302
B13: Sanofi | C13: SNY | D13: Comitted | E13: 0.4 | F13: =Assumptions!$G$7+Assumptions!$I$7*DCF!$E13 -> 0.05022 | G13: 749000 | H13: 17906000 | I13: =$G13/$H13 -> 0.041829554 | J13: 0.3613 | K13: =$I13*(1-$J13) -> 0.026716536 | L13: 116030000000 | M13: =$L13/($L13+$H13) -> 0.9998457 | N13: =$H13/($H13+$L13) -> 0.00015429835 | O13: =$F13*$M13+$I13*$N13 -> 0.050218705 | R13: =1/(1+$O13)^1 -> 0.95218262 | S13: =1/(1+$O13)^2 -> 0.90665174 | T13: =1/(1+$O13)^3 -> 0.86329803 | U13: =1/(1+$O13)^4 -> 0.82201739 | V13: =1/(1+$O13)^5 -> 0.78271067 | W13: =1/(1+$O13)^6 -> 0.7452835 | X13: =1/(1+$O13)^7 -> 0.70964599 | Y13: =1/(1+$O13)^8 -> 0.67571258 | Z13: =1/(1+$O13)^9 -> 0.64340178 | AA13: =1/(1+$O13)^10 -> 0.61263599
B14: UCB SA | C14: UCB.BR | D14: None | E14: 0.25 | F14: =Assumptions!$G$7+Assumptions!$I$7*DCF!$E14 -> 0.04197 | G14: 159000 | H14: 3026000 | I14: =$G14/$H14 -> 0.052544613 | J14: 0.25 | K14: =$I14*(1-$J14) -> 0.03940846 | L14: 47860000000 | M14: =$L14/($L14+$H14) -> 0.99993678 | N14: =$H14/($H14+$L14) -> 6.3222079e-05 | O14: =$F14*$M14+$I14*$N14 -> 0.041970669 | R14: =1/(1+$O14)^1 -> 0.95971991 | S14: =1/(1+$O14)^2 -> 0.92106231 | T14: =1/(1+$O14)^3 -> 0.88396184 | U14: =1/(1+$O14)^4 -> 0.84835578 | V14: =1/(1+$O14)^5 -> 0.81418394 | W14: =1/(1+$O14)^6 -> 0.78138854 | X14: =1/(1+$O14)^7 -> 0.74991414 | Y14: =1/(1+$O14)^8 -> 0.71970754 | Z14: =1/(1+$O14)^9 -> 0.69071765 | AA14: =1/(1+$O14)^10 -> 0.66289549
B15: GSK plc | C15: GSK | D15: None | E15: 0.25 | F15: =Assumptions!$G$7+Assumptions!$I$7*DCF!$E15 -> 0.04197 | G15: 640000 | H15: 16986000 | I15: =$G15/$H15 -> 0.037678088 | J15: 0.25 | K15: =$I15*(1-$J15) -> 0.028258566 | L15: 99750000000 | M15: =$L15/($L15+$H15) -> 0.99982974 | N15: =$H15/($H15+$L15) -> 0.00017025672 | O15: =$F15*$M15+$I15*$N15 -> 0.041969269 | R15: =1/(1+$O15)^1 -> 0.9597212 | S15: =1/(1+$O15)^2 -> 0.92106479 | T15: =1/(1+$O15)^3 -> 0.8839654 | U15: =1/(1+$O15)^4 -> 0.84836034 | V15: =1/(1+$O15)^5 -> 0.81418941 | W15: =1/(1+$O15)^6 -> 0.78139484 | X15: =1/(1+$O15)^7 -> 0.74992119 | Y15: =1/(1+$O15)^8 -> 0.71971527 | Z15: =1/(1+$O15)^9 -> 0.690726 | AA15: =1/(1+$O15)^10 -> 0.66290439
B16: BioNTech SE | C16: BNTX | D16: None | E16: 1.41 | F16: =Assumptions!$G$7+Assumptions!$I$7*DCF!$E16 -> 0.10577 | G16: 12600 | H16: 254200 | I16: =$G16/$H16 -> 0.04956727 | J16: 0.3006 | K16: =$I16*(1-$J16) -> 0.034667349 | L16: 25640000000 | M16: =$L16/($L16+$H16) -> 0.99999009 | N16: =$H16/($H16+$L16) -> 9.9140983e-06 | O16: =$F16*$M16+$I16*$N16 -> 0.10576944 | R16: =1/(1+$O16)^1 -> 0.90434765 | S16: =1/(1+$O16)^2 -> 0.81784468 | T16: =1/(1+$O16)^3 -> 0.73961591 | U16: =1/(1+$O16)^4 -> 0.66886992 | V16: =1/(1+$O16)^5 -> 0.60489094 | W16: =1/(1+$O16)^6 -> 0.5470317 | X16: =1/(1+$O16)^7 -> 0.49470683 | Y16: =1/(1+$O16)^8 -> 0.44738696 | Z16: =1/(1+$O16)^9 -> 0.40459335 | AA16: =1/(1+$O16)^10 -> 0.36589305
B17: Pfizer | C17: PFE.DE | D17: Commited | E17: 0.43 | F17: =Assumptions!$G$7+Assumptions!$I$7*DCF!$E17 -> 0.05187 | G17: 3091000 | H17: 63649000 | I17: =$G17/$H17 -> 0.048563214 | J17: 0.2557 | K17: =$I17*(1-$J17) -> 0.0361456 | L17: 144480000000 | M17: =$L17/($L17+$H17) -> 0.99955966 | N17: =$H17/($H17+$L17) -> 0.00044034449 | O17: =$F17*$M17+$I17*$N17 -> 0.051868544 | R17: =1/(1+$O17)^1 -> 0.95068914 | S17: =1/(1+$O17)^2 -> 0.90380984 | T17: =1/(1+$O17)^3 -> 0.8592422 | U17: =1/(1+$O17)^4 -> 0.81687222 | V17: =1/(1+$O17)^5 -> 0.77659155 | W17: =1/(1+$O17)^6 -> 0.73829715 | X17: =1/(1+$O17)^7 -> 0.70189108 | Y17: =1/(1+$O17)^8 -> 0.66728023 | Z17: =1/(1+$O17)^9 -> 0.63437607 | AA17: =1/(1+$O17)^10 -> 0.60309444
B18: Johnson & Johnson | C18: JNJ.DE | D18: None | E18: 0.33 | F18: =Assumptions!$G$7+Assumptions!$I$7*DCF!$E18 -> 0.04637 | G18: 755000 | H18: 36634000 | I18: =$G18/$H18 -> 0.02060927 | J18: 0.2557 | K18: =$I18*(1-$J18) -> 0.01533948 | L18: 453830000000 | M18: =$L18/($L18+$H18) -> 0.99991928 | N18: =$H18/($H18+$L18) -> 8.0715341e-05 | O18: =$F18*$M18+$I18*$N18 -> 0.046367921 | R18: =1/(1+$O18)^1 -> 0.95568679 | S18: =1/(1+$O18)^2 -> 0.91333724 | T18: =1/(1+$O18)^3 -> 0.87286434 | U18: =1/(1+$O18)^4 -> 0.83418492 | V18: =1/(1+$O18)^5 -> 0.79721951 | W18: =1/(1+$O18)^6 -> 0.76189215 | X18: =1/(1+$O18)^7 -> 0.72813027 | Y18: =1/(1+$O18)^8 -> 0.69586448 | Z18: =1/(1+$O18)^9 -> 0.66502849 | AA18: =1/(1+$O18)^10 -> 0.63555894
B21: Transport
R22: =1/(1+$O22)^1 -> 1 | S22: =1/(1+$O22)^2 -> 1 | T22: =1/(1+$O22)^3 -> 1 | U22: =1/(1+$O22)^4 -> 1 | V22: =1/(1+$O22)^5 -> 1 | W22: =1/(1+$O22)^6 -> 1 | X22: =1/(1+$O22)^7 -> 1 | Y22: =1/(1+$O22)^8 -> 1 | Z22: =1/(1+$O22)^9 -> 1 | AA22: =1/(1+$O22)^10 -> 1
B24: PostNL | C24: PNL.AS | D24: Platinum | E24: 0.72 | F24: =Assumptions!$G$7+Assumptions!$I$7*DCF!$E24 -> 0.06782 | G24: 33000 | H24: 972000 | I24: =$G24/$H24 -> 0.033950617 | J24: 0.258 | K24: =$I24*(1-$J24) -> 0.025191358 | L24: 469510000 | M24: =$L24/($L24+$H24) -> 0.99793403 | N24: =$H24/($H24+$L24) -> 0.0020659664 | O24: =$F24*$M24+$I24*$N24 -> 0.067750027 | R24: =1/(1+$O24)^1 -> 0.93654879 | S24: =1/(1+$O24)^2 -> 0.87712364 | T24: =1/(1+$O24)^3 -> 0.82146909 | U24: =1/(1+$O24)^4 -> 0.76934589 | V24: =1/(1+$O24)^5 -> 0.72052996 | W24: =1/(1+$O24)^6 -> 0.67481147 | X24: =1/(1+$O24)^7 -> 0.63199387 | Y24: =1/(1+$O24)^8 -> 0.59189309 | Z24: =1/(1+$O24)^9 -> 0.55433676 | AA24: =1/(1+$O24)^10 -> 0.51916343
B25: DHL Group | C25: DHL.DE | D25: Gold | E25: 1.17 | F25: =Assumptions!$G$7+Assumptions!$I$7*DCF!$E25 -> 0.09257 | G25: 1034000 | H25: 22442000 | I25: =$G25/$H25 -> 0.046074325 | J25: 0.3006 | K25: =$I25*(1-$J25) -> 0.032224383 | L25: 54430000000 | M25: =$L25/($L25+$H25) -> 0.99958786 | N25: =$H25/($H25+$L25) -> 0.00041213946 | O25: =$F25*$M25+$I25*$N25 -> 0.092550837 | R25: =1/(1+$O25)^1 -> 0.91528922 | S25: =1/(1+$O25)^2 -> 0.83775435 | T25: =1/(1+$O25)^3 -> 0.76678752 | U25: =1/(1+$O25)^4 -> 0.70183235 | V25: =1/(1+$O25)^5 -> 0.64237958 | W25: =1/(1+$O25)^6 -> 0.58796311 | X25: =1/(1+$O25)^7 -> 0.53815629 | Y25: =1/(1+$O25)^8 -> 0.49256865 | Z25: =1/(1+$O25)^9 -> 0.45084277 | AA25: =1/(1+$O25)^10 -> 0.41265153
B26: XPO Logistics | C26: XPO | D26: Gold | E26: 1.8 | F26: =Assumptions!$G$7+Assumptions!$I$7*DCF!$E26 -> 0.12722 | G26: 223000 | H26: 4117000 | I26: =$G26/$H26 -> 0.054165655 | J26: 0.2557 | K26: =$I26*(1-$J26) -> 0.040315497 | L26: 17150000000 | M26: =$L26/($L26+$H26) -> 0.99976 | N26: =$H26/($H26+$L26) -> 0.00024000069 | O26: =$F26*$M26+$I26*$N26 -> 0.12720247 | R26: =1/(1+$O26)^1 -> 0.88715207 | S26: =1/(1+$O26)^2 -> 0.78703879 | T26: =1/(1+$O26)^3 -> 0.69822309 | U26: =1/(1+$O26)^4 -> 0.61943006 | V26: =1/(1+$O26)^5 -> 0.54952866 | W26: =1/(1+$O26)^6 -> 0.48751549 | X26: =1/(1+$O26)^7 -> 0.43250037 | Y26: =1/(1+$O26)^8 -> 0.3836936 | Z26: =1/(1+$O26)^9 -> 0.34039457 | AA26: =1/(1+$O26)^10 -> 0.30198175
B27: Logista | C27: 5CI.F | D27: Silver | E27: 0.5 | F27: =Assumptions!$G$7+Assumptions!$I$7*DCF!$E27 -> 0.05572 | G27: 8319 | H27: 276439 | I27: =$G27/$H27 -> 0.030093438 | J27: 0.25 | K27: =$I27*(1-$J27) -> 0.022570079 | L27: 4090000000 | M27: =$L27/($L27+$H27) -> 0.99993242 | N27: =$H27/($H27+$L27) -> 6.758443e-05 | O27: =$F27*$M27+$I27*$N27 -> 0.055718268 | R27: =1/(1+$O27)^1 -> 0.94722241 | S27: =1/(1+$O27)^2 -> 0.89723029 | T27: =1/(1+$O27)^3 -> 0.84987664 | U27: =1/(1+$O27)^4 -> 0.80502219 | V27: =1/(1+$O27)^5 -> 0.76253506 | W27: =1/(1+$O27)^6 -> 0.7222903 | X27: =1/(1+$O27)^7 -> 0.68416955 | Y27: =1/(1+$O27)^8 -> 0.64806073 | Z27: =1/(1+$O27)^9 -> 0.61385765 | AA27: =1/(1+$O27)^10 -> 0.58145972
B28: Kuehne + Nagel | C28: KNIN.SW | D28: None | E28: 0.81 | F28: =Assumptions!$G$7+Assumptions!$I$7*DCF!$E28 -> 0.07277 | G28: 37000 | H28: 2346000 | I28: =$G28/$H28 -> 0.015771526 | J28: 0.1961 | K28: =$I28*(1-$J28) -> 0.01267873 | L28: 24670000000 | M28: =$L28/($L28+$H28) -> 0.99990491 | N28: =$H28/($H28+$L28) -> 9.5086215e-05 | O28: =$F28*$M28+$I28*$N28 -> 0.07276458 | R28: =1/(1+$O28)^1 -> 0.93217097 | S28: =1/(1+$O28)^2 -> 0.86894272 | T28: =1/(1+$O28)^3 -> 0.81000318 | U28: =1/(1+$O28)^4 -> 0.75506145 | V28: =1/(1+$O28)^5 -> 0.70384636 | W28: =1/(1+$O28)^6 -> 0.65610515 | X28: =1/(1+$O28)^7 -> 0.61160217 | Y28: =1/(1+$O28)^8 -> 0.57011779 | Z28: =1/(1+$O28)^9 -> 0.53144725 | AA28: =1/(1+$O28)^10 -> 0.4953997
B29: C.H. Robinson | C29: CHRW | D29: None | E29: 0.91 | F29: =Assumptions!$G$7+Assumptions!$I$7*DCF!$E29 -> 0.07827 | G29: 73029 | H29: 1741132 | I29: =$G29/$H29 -> 0.041943402 | J29: 0.2557 | K29: =$I29*(1-$J29) -> 0.031218474 | L29: 15680000000 | M29: =$L29/($L29+$H29) -> 0.99988897 | N29: =$H29/($H29+$L29) -> 0.00011102925 | O29: =$F29*$M29+$I29*$N29 -> 0.078265967 | R29: =1/(1+$O29)^1 -> 0.92741497 | S29: =1/(1+$O29)^2 -> 0.86009853 | T29: =1/(1+$O29)^3 -> 0.79766825 | U29: =1/(1+$O29)^4 -> 0.73976948 | V29: =1/(1+$O29)^5 -> 0.68607329 | W29: =1/(1+$O29)^6 -> 0.63627464 | X29: =1/(1+$O29)^7 -> 0.59009063 | Y29: =1/(1+$O29)^8 -> 0.54725888 | Z29: =1/(1+$O29)^9 -> 0.50753608 | AA29: =1/(1+$O29)^10 -> 0.47069656
B31: Energy
R32: =1/(1+$O32)^1 -> 1 | S32: =1/(1+$O32)^2 -> 1 | T32: =1/(1+$O32)^3 -> 1 | U32: =1/(1+$O32)^4 -> 1 | V32: =1/(1+$O32)^5 -> 1 | W32: =1/(1+$O32)^6 -> 1 | X32: =1/(1+$O32)^7 -> 1 | Y32: =1/(1+$O32)^8 -> 1 | Z32: =1/(1+$O32)^9 -> 1 | AA32: =1/(1+$O32)^10 -> 1
B33: Iberdrola | C33: IBE5.F | D33: None | E33: 0.65 | F33: =Assumptions!$G$7+Assumptions!$I$7*DCF!$E33 -> 0.06397 | G33: 1997000 | H33: 57731000 | I33: =$G33/$H33 -> 0.034591467 | J33: 0.25 | K33: =$I33*(1-$J33) -> 0.0259436 | L33: 126280000000 | M33: =$L33/($L33+$H33) -> 0.99954304 | N33: =$H33/($H33+$L33) -> 0.00045695771 | O33: =$F33*$M33+$I33*$N33 -> 0.063956575 | R33: =1/(1+$O33)^1 -> 0.93988798 | S33: =1/(1+$O33)^2 -> 0.88338942 | T33: =1/(1+$O33)^3 -> 0.8302871 | U33: =1/(1+$O33)^4 -> 0.78037687 | V33: =1/(1+$O33)^5 -> 0.73346684 | W33: =1/(1+$O33)^6 -> 0.68937667 | X33: =1/(1+$O33)^7 -> 0.64793685 | Y33: =1/(1+$O33)^8 -> 0.60898806 | Z33: =1/(1+$O33)^9 -> 0.57238056 | AA33: =1/(1+$O33)^10 -> 0.53797361
B34: Elia | C34: ELIAF | D34: None | E34: 0.75 | F34: =Assumptions!$G$7+Assumptions!$I$7*DCF!$E34 -> 0.06947 | G34: 235800 | H34: 14828400 | I34: =$G34/$H34 -> 0.015901918 | J34: 0.25 | K34: =$I34*(1-$J34) -> 0.011926438 | L34: 12560000000 | M34: =$L34/($L34+$H34) -> 0.99882079 | N34: =$H34/($H34+$L34) -> 0.0011792129 | O34: =$F34*$M34+$I34*$N34 -> 0.069406832 | R34: =1/(1+$O34)^1 -> 0.93509782 | S34: =1/(1+$O34)^2 -> 0.87440794 | T34: =1/(1+$O34)^3 -> 0.81765696 | U34: =1/(1+$O34)^4 -> 0.76458924 | V34: =1/(1+$O34)^5 -> 0.71496574 | W34: =1/(1+$O34)^6 -> 0.6685629 | X34: =1/(1+$O34)^7 -> 0.62517171 | Y34: =1/(1+$O34)^8 -> 0.58459671 | Z34: =1/(1+$O34)^9 -> 0.54665511 | AA34: =1/(1+$O34)^10 -> 0.511176
B35: Engie | C35: ENGIY | D35: Platinum | E35: 0.52 | F35: =Assumptions!$G$7+Assumptions!$I$7*DCF!$E35 -> 0.05682 | G35: 2967000 | H35: 52007000 | I35: =$G35/$H35 -> 0.057050012 | J35: 0.3613 | K35: =$I35*(1-$J35) -> 0.036437843 | L35: 67300000000 | M35: =$L35/($L35+$H35) -> 0.99922783 | N35: =$H35/($H35+$L35) -> 0.00077216704 | O35: =$F35*$M35+$I35*$N35 -> 0.056820178 | R35: =1/(1+$O35)^1 -> 0.94623477 | S35: =1/(1+$O35)^2 -> 0.89536024 | T35: =1/(1+$O35)^3 -> 0.847221 | U35: =1/(1+$O35)^4 -> 0.80166997 | V35: =1/(1+$O35)^5 -> 0.758568 | W35: =1/(1+$O35)^6 -> 0.71778342 | X35: =1/(1+$O35)^7 -> 0.67919163 | Y35: =1/(1+$O35)^8 -> 0.64267474 | Z35: =1/(1+$O35)^9 -> 0.60812118 | AA35: =1/(1+$O35)^10 -> 0.57542541
B36: TotalEnergies SE | C36: TTE.PA | D36: Platinum | E36: 0.23 | F36: =Assumptions!$G$7+Assumptions!$I$7*DCF!$E36 -> 0.04087 | G36: 2364000 | H36: 51244000 | I36: =$G36/$H36 -> 0.04613223 | J36: 0.3613 | K36: =$I36*(1-$J36) -> 0.029464655 | L36: 118520000000 | M36: =$L36/($L36+$H36) -> 0.99956782 | N36: =$H36/($H36+$L36) -> 0.00043217899 | O36: =$F36*$M36+$I36*$N36 -> 0.040872274 | R36: =1/(1+$O36)^1 -> 0.96073267 | S36: =1/(1+$O36)^2 -> 0.92300726 | T36: =1/(1+$O36)^3 -> 0.88676323 | U36: =1/(1+$O36)^4 -> 0.85194241 | V36: =1/(1+$O36)^5 -> 0.81848891 | W36: =1/(1+$O36)^6 -> 0.78634903 | X36: =1/(1+$O36)^7 -> 0.75547121 | Y36: =1/(1+$O36)^8 -> 0.72580587 | Z36: =1/(1+$O36)^9 -> 0.69730541 | AA36: =1/(1+$O36)^10 -> 0.66992409
B37: Orsted | C37: D2G.F | D37: Gold | E37: 0.62 | F37: =Assumptions!$G$7+Assumptions!$I$7*DCF!$E37 -> 0.06232 | G37: 4007000 | H37: 96618000 | I37: =$G37/$H37 -> 0.041472603 | J37: 0.22 | K37: =$I37*(1-$J37) -> 0.032348631 | L37: 23060000000 | M37: =$L37/($L37+$H37) -> 0.99582763 | N37: =$H37/($H37+$L37) -> 0.0041723709 | O37: =$F37*$M37+$I37*$N37 -> 0.062233017 | R37: =1/(1+$O37)^1 -> 0.94141303 | S37: =1/(1+$O37)^2 -> 0.88625849 | T37: =1/(1+$O37)^3 -> 0.83433529 | U37: =1/(1+$O37)^4 -> 0.78545411 | V37: =1/(1+$O37)^5 -> 0.73943673 | W37: =1/(1+$O37)^6 -> 0.69611537 | X37: =1/(1+$O37)^7 -> 0.65533208 | Y37: =1/(1+$O37)^8 -> 0.61693815 | Z37: =1/(1+$O37)^9 -> 0.58079362 | AA37: =1/(1+$O37)^10 -> 0.54676668
B38: Shell plc | C38: SHELL.AS | D38: None | E38: -0.1 | F38: =Assumptions!$G$7+Assumptions!$I$7*DCF!$E38 -> 0.02272 | G38: 4858000 | H38: 77078000 | I38: =$G38/$H38 -> 0.063027063 | J38: 0.25 | K38: =$I38*(1-$J38) -> 0.047270298 | L38: 172720000000 | M38: =$L38/($L38+$H38) -> 0.99955394 | N38: =$H38/($H38+$L38) -> 0.00044606078 | O38: =$F38*$M38+$I38*$N38 -> 0.022737979 | R38: =1/(1+$O38)^1 -> 0.97776754 | S38: =1/(1+$O38)^2 -> 0.95602937 | T38: =1/(1+$O38)^3 -> 0.93477448 | U38: =1/(1+$O38)^4 -> 0.91399215 | V38: =1/(1+$O38)^5 -> 0.89367186 | W38: =1/(1+$O38)^6 -> 0.87380333 | X38: =1/(1+$O38)^7 -> 0.85437654 | Y38: =1/(1+$O38)^8 -> 0.83538165 | Z38: =1/(1+$O38)^9 -> 0.81680906 | AA38: =1/(1+$O38)^10 -> 0.79864939

Sheet NPV_Output
B2: Carbon Costs & NPV
B5: Policy Regime : | C5: =ControlPanel!$C$6 -> accelerated
B6: Price Percentile : | C6: =ControlPanel!$C$7 -> P75
B8: Carbon Costs | C8: 2026 | D8: =C8+1 -> 2027 | E8: =D8+1 -> 2028 | F8: =E8+1 -> 2029 | G8: =F8+1 -> 2030 | H8: =G8+1 -> 2031 | I8: =H8+1 -> 2032 | J8: =I8+1 -> 2033 | K8: =J8+1 -> 2034 | L8: =K8+1 -> 2035 | N8: NPV
B10: Life Sciences
B12: AstraZeneca PLC | C12: {='Carbon_Emission&Exposure'!G9*_xlfn.XLOOKUP(NPV_Output!C$8,_xlfn.ANCHORARRAY( ControlPanel!$B$10),_xlfn.ANCHORARRAY( ControlPanel!$C$10))*Assumptions!$O$12} -> 5648051.9 | D12: {='Carbon_Emission&Exposure'!H9*_xlfn.XLOOKUP(NPV_Output!D$8,_xlfn.ANCHORARRAY( ControlPanel!$B$10),_xlfn.ANCHORARRAY( ControlPanel!$C$10))*Assumptions!$O$12} -> 6897518 | E12: {='Carbon_Emission&Exposure'!I9*_xlfn.XLOOKUP(NPV_Output!E$8,_xlfn.ANCHORARRAY( ControlPanel!$B$10),_xlfn.ANCHORARRAY( ControlPanel!$C$10))*Assumptions!$O$12} -> 7624519.1 | F12: {='Carbon_Emission&Exposure'!J9*_xlfn.XLOOKUP(NPV_Output!F$8,_xlfn.ANCHORARRAY( ControlPanel!$B$10),_xlfn.ANCHORARRAY( ControlPanel!$C$10))*Assumptions!$O$12} -> 8304529.5 | G12: {='Carbon_Emission&Exposure'!K9*_xlfn.XLOOKUP(NPV_Output!G$8,_xlfn.ANCHORARRAY( ControlPanel!$B$10),_xlfn.ANCHORARRAY( ControlPanel!$C$10))*Assumptions!$O$12} -> 8955292.5 | H12: {='Carbon_Emission&Exposure'!L9*_xlfn.XLOOKUP(NPV_Output!H$8,_xlfn.ANCHORARRAY( ControlPanel!$B$10),_xlfn.ANCHORARRAY( ControlPanel!$C$10))*Assumptions!$O$12} -> 9610745 | I12: {='Carbon_Emission&Exposure'!M9*_xlfn.XLOOKUP(NPV_Output!I$8,_xlfn.ANCHORARRAY( ControlPanel!$B$10),_xlfn.ANCHORARRAY( ControlPanel!$C$10))*Assumptions!$O$12} -> 10278125 | J12: {='Carbon_Emission&Exposure'!N9*_xlfn.XLOOKUP(NPV_Output!J$8,_xlfn.ANCHORARRAY( ControlPanel!$B$10),_xlfn.ANCHORARRAY( ControlPanel!$C$10))*Assumptions!$O$12} -> 10955400 | ... L12: {='Carbon_Emission&Exposure'!P9*_xlfn.XLOOKUP(NPV_Output!L$8,_xlfn.ANCHORARRAY( ControlPanel!$B$10),_xlfn.ANCHORARRAY( ControlPanel!$C$10))*Assumptions!$O$12} -> 12365471 | N12: =SUMPRODUCT(C12:L12,DCF!R9:AA9) -> 73541710
B13: Bayer AG | C13: {='Carbon_Emission&Exposure'!G10*_xlfn.XLOOKUP(NPV_Output!C$8,_xlfn.ANCHORARRAY( ControlPanel!$B$10),_xlfn.ANCHORARRAY( ControlPanel!$C$10))*Assumptions!$O$12} -> 2236424.9 | D13: {='Carbon_Emission&Exposure'!H10*_xlfn.XLOOKUP(NPV_Output!D$8,_xlfn.ANCHORARRAY( ControlPanel!$B$10),_xlfn.ANCHORARRAY( ControlPanel!$C$10))*Assumptions!$O$12} -> 2731168.5 | E13: {='Carbon_Emission&Exposure'!I10*_xlfn.XLOOKUP(NPV_Output!E$8,_xlfn.ANCHORARRAY( ControlPanel!$B$10),_xlfn.ANCHORARRAY( ControlPanel!$C$10))*Assumptions!$O$12} -> 3019034.7 | F13: {='Carbon_Emission&Exposure'!J10*_xlfn.XLOOKUP(NPV_Output!F$8,_xlfn.ANCHORARRAY( ControlPanel!$B$10),_xlfn.ANCHORARRAY( ControlPanel!$C$10))*Assumptions!$O$12} -> 3288294.3 | G13: {='Carbon_Emission&Exposure'!K10*_xlfn.XLOOKUP(NPV_Output!G$8,_xlfn.ANCHORARRAY( ControlPanel!$B$10),_xlfn.ANCHORARRAY( ControlPanel!$C$10))*Assumptions!$O$12} -> 3545973 | H13: {='Carbon_Emission&Exposure'!L10*_xlfn.XLOOKUP(NPV_Output!H$8,_xlfn.ANCHORARRAY( ControlPanel!$B$10),_xlfn.ANCHORARRAY( ControlPanel!$C$10))*Assumptions!$O$12} -> 3805508.6 | I13: {='Carbon_Emission&Exposure'!M10*_xlfn.XLOOKUP(NPV_Output!I$8,_xlfn.ANCHORARRAY( ControlPanel!$B$10),_xlfn.ANCHORARRAY( ControlPanel!$C$10))*Assumptions!$O$12} -> 4069766.9 | J13: {='Carbon_Emission&Exposure'!N10*_xlfn.XLOOKUP(NPV_Output!J$8,_xlfn.ANCHORARRAY( ControlPanel!$B$10),_xlfn.ANCHORARRAY( ControlPanel!$C$10))*Assumptions!$O$12} -> 4337943.6 | ... L13: {='Carbon_Emission&Exposure'!P10*_xlfn.XLOOKUP(NPV_Output!L$8,_xlfn.ANCHORARRAY( ControlPanel!$B$10),_xlfn.ANCHORARRAY( ControlPanel!$C$10))*Assumptions!$O$12} -> 4896280.7 | N13: =SUMPRODUCT(C13:L13,DCF!R10:AA10) -> 23675157
B14: Novartis AG | C14: {='Carbon_Emission&Exposure'!G11*_xlfn.XLOOKUP(NPV_Output!C$8,_xlfn.ANCHORARRAY( ControlPanel!$B$10),_xlfn.ANCHORARRAY( ControlPanel!$C$10))*Assumptions!$O$12} -> 6894905.8 | D14: {='Carbon_Emission&Exposure'!H11*_xlfn.XLOOKUP(NPV_Output!D$8,_xlfn.ANCHORARRAY( ControlPanel!$B$10),_xlfn.ANCHORARRAY( ControlPanel!$C$10))*Assumptions!$O$12} -> 8420201.8 | E14: {='Carbon_Emission&Exposure'!I11*_xlfn.XLOOKUP(NPV_Output!E$8,_xlfn.ANCHORARRAY( ControlPanel!$B$10),_xlfn.ANCHORARRAY( ControlPanel!$C$10))*Assumptions!$O$12} -> 9307694.5 | F14: {='Carbon_Emission&Exposure'!J11*_xlfn.XLOOKUP(NPV_Output!F$8,_xlfn.ANCHORARRAY( ControlPanel!$B$10),_xlfn.ANCHORARRAY( ControlPanel!$C$10))*Assumptions!$O$12} -> 10137823 | G14: {='Carbon_Emission&Exposure'!K11*_xlfn.XLOOKUP(NPV_Output!G$8,_xlfn.ANCHORARRAY( ControlPanel!$B$10),_xlfn.ANCHORARRAY( ControlPanel!$C$10))*Assumptions!$O$12} -> 10932247 | H14: {='Carbon_Emission&Exposure'!L11*_xlfn.XLOOKUP(NPV_Output!H$8,_xlfn.ANCHORARRAY( ControlPanel!$B$10),_xlfn.ANCHORARRAY( ControlPanel!$C$10))*Assumptions!$O$12} -> 11732396 | I14: {='Carbon_Emission&Exposure'!M11*_xlfn.XLOOKUP(NPV_Output!I$8,_xlfn.ANCHORARRAY( ControlPanel!$B$10),_xlfn.ANCHORARRAY( ControlPanel!$C$10))*Assumptions!$O$12} -> 12547105 | J14: {='Carbon_Emission&Exposure'!N11*_xlfn.XLOOKUP(NPV_Output!J$8,_xlfn.ANCHORARRAY( ControlPanel!$B$10),_xlfn.ANCHORARRAY( ControlPanel!$C$10))*Assumptions!$O$12} -> 13373895 | ... L14: {='Carbon_Emission&Exposure'!P11*_xlfn.XLOOKUP(NPV_Output!L$8,_xlfn.ANCHORARRAY( ControlPanel!$B$10),_xlfn.ANCHORARRAY( ControlPanel!$C$10))*Assumptions!$O$12} -> 15095250 | N14: =SUMPRODUCT(C14:L14,DCF!R11:AA11) -> 82955182
B15: Roche Holding AG | C15: {='Carbon_Emission&Exposure'!G12*_xlfn.XLOOKUP(NPV_Output!C$8,_xlfn.ANCHORARRAY( ControlPanel!$B$10),_xlfn.ANCHORARRAY( ControlPanel!$C$10))*Assumptions!$O$12} -> 6481593.3 | D15: {='Carbon_Emission&Exposure'!H12*_xlfn.XLOOKUP(NPV_Output!D$8,_xlfn.ANCHORARRAY( ControlPanel!$B$10),_xlfn.ANCHORARRAY( ControlPanel!$C$10))*Assumptions!$O$12} -> 7915456 | E15: {='Carbon_Emission&Exposure'!I12*_xlfn.XLOOKUP(NPV_Output!E$8,_xlfn.ANCHORARRAY( ControlPanel!$B$10),_xlfn.ANCHORARRAY( ControlPanel!$C$10))*Assumptions!$O$12} -> 8749748.2 | F15: {='Carbon_Emission&Exposure'!J12*_xlfn.XLOOKUP(NPV_Output!F$8,_xlfn.ANCHORARRAY( ControlPanel!$B$10),_xlfn.ANCHORARRAY( ControlPanel!$C$10))*Assumptions!$O$12} -> 9530114.7 | G15: {='Carbon_Emission&Exposure'!K12*_xlfn.XLOOKUP(NPV_Output!G$8,_xlfn.ANCHORARRAY( ControlPanel!$B$10),_xlfn.ANCHORARRAY( ControlPanel!$C$10))*Assumptions!$O$12} -> 10276918 | H15: {='Carbon_Emission&Exposure'!L12*_xlfn.XLOOKUP(NPV_Output!H$8,_xlfn.ANCHORARRAY( ControlPanel!$B$10),_xlfn.ANCHORARRAY( ControlPanel!$C$10))*Assumptions!$O$12} -> 11029102 | I15: {='Carbon_Emission&Exposure'!M12*_xlfn.XLOOKUP(NPV_Output!I$8,_xlfn.ANCHORARRAY( ControlPanel!$B$10),_xlfn.ANCHORARRAY( ControlPanel!$C$10))*Assumptions!$O$12} -> 11794974 | J15: {='Carbon_Emission&Exposure'!N12*_xlfn.XLOOKUP(NPV_Output!J$8,_xlfn.ANCHORARRAY( ControlPanel!$B$10),_xlfn.ANCHORARRAY( ControlPanel!$C$10))*Assumptions!$O$12} -> 12572202 | ... L15: {='Carbon_Emission&Exposure'!P12*_xlfn.XLOOKUP(NPV_Output!L$8,_xlfn.ANCHORARRAY( ControlPanel!$B$10),_xlfn.ANCHORARRAY( ControlPanel!$C$10))*Assumptions!$O$12} -> 14190371 | N15: =SUMPRODUCT(C15:L15,DCF!R12:AA12) -> 84919631
B16: Sanofi | C16: {='Carbon_Emission&Exposure'!G13*_xlfn.XLOOKUP(NPV_Output!C$8,_xlfn.ANCHORARRAY( ControlPanel!$B$10),_xlfn.ANCHORARRAY( ControlPanel!$C$10))*Assumptions!$O$12} -> 3412180.3 | D16: {='Carbon_Emission&Exposure'!H13*_xlfn.XLOOKUP(NPV_Output!D$8,_xlfn.ANCHORARRAY( ControlPanel!$B$10),_xlfn.ANCHORARRAY( ControlPanel!$C$10))*Assumptions!$O$12} -> 4167025.2 | E16: {='Carbon_Emission&Exposure'!I13*_xlfn.XLOOKUP(NPV_Output!E$8,_xlfn.ANCHORARRAY( ControlPanel!$B$10),_xlfn.ANCHORARRAY( ControlPanel!$C$10))*Assumptions!$O$12} -> 4606231.3 | F16: {='Carbon_Emission&Exposure'!J13*_xlfn.XLOOKUP(NPV_Output!F$8,_xlfn.ANCHORARRAY( ControlPanel!$B$10),_xlfn.ANCHORARRAY( ControlPanel!$C$10))*Assumptions!$O$12} -> 5017048.7 | G16: {='Carbon_Emission&Exposure'!K13*_xlfn.XLOOKUP(NPV_Output!G$8,_xlfn.ANCHORARRAY( ControlPanel!$B$10),_xlfn.ANCHORARRAY( ControlPanel!$C$10))*Assumptions!$O$12} -> 5410196.8 | H16: {='Carbon_Emission&Exposure'!L13*_xlfn.XLOOKUP(NPV_Output!H$8,_xlfn.ANCHORARRAY( ControlPanel!$B$10),_xlfn.ANCHORARRAY( ControlPanel!$C$10))*Assumptions!$O$12} -> 5806177.9 | I16: {='Carbon_Emission&Exposure'!M13*_xlfn.XLOOKUP(NPV_Output!I$8,_xlfn.ANCHORARRAY( ControlPanel!$B$10),_xlfn.ANCHORARRAY( ControlPanel!$C$10))*Assumptions!$O$12} -> 6209364.8 | J16: {='Carbon_Emission&Exposure'!N13*_xlfn.XLOOKUP(NPV_Output!J$8,_xlfn.ANCHORARRAY( ControlPanel!$B$10),_xlfn.ANCHORARRAY( ControlPanel!$C$10))*Assumptions!$O$12} -> 6618530 | ... L16: {='Carbon_Emission&Exposure'!P13*_xlfn.XLOOKUP(NPV_Output!L$8,_xlfn.ANCHORARRAY( ControlPanel!$B$10),_xlfn.ANCHORARRAY( ControlPanel!$C$10))*Assumptions!$O$12} -> 7470401.6 | N16: =SUMPRODUCT(C16:L16,DCF!R13:AA13) -> 41673518
B17: UCB SA | C17: {='Carbon_Emission&Exposure'!G14*_xlfn.XLOOKUP(NPV_Output!C$8,_xlfn.ANCHORARRAY( ControlPanel!$B$10),_xlfn.ANCHORARRAY( ControlPanel!$C$10))*Assumptions!$O$12} -> 512352.67 | D17: {='Carbon_Emission&Exposure'!H14*_xlfn.XLOOKUP(NPV_Output!D$8,_xlfn.ANCHORARRAY( ControlPanel!$B$10),_xlfn.ANCHORARRAY( ControlPanel!$C$10))*Assumptions!$O$12} -> 625695.7 | E17: {='Carbon_Emission&Exposure'!I14*_xlfn.XLOOKUP(NPV_Output!E$8,_xlfn.ANCHORARRAY( ControlPanel!$B$10),_xlfn.ANCHORARRAY( ControlPanel!$C$10))*Assumptions!$O$12} -> 691644.27 | F17: {='Carbon_Emission&Exposure'!J14*_xlfn.XLOOKUP(NPV_Output!F$8,_xlfn.ANCHORARRAY( ControlPanel!$B$10),_xlfn.ANCHORARRAY( ControlPanel!$C$10))*Assumptions!$O$12} -> 753330.16 | G17: {='Carbon_Emission&Exposure'!K14*_xlfn.XLOOKUP(NPV_Output!G$8,_xlfn.ANCHORARRAY( ControlPanel!$B$10),_xlfn.ANCHORARRAY( ControlPanel!$C$10))*Assumptions!$O$12} -> 812362.94 | H17: {='Carbon_Emission&Exposure'!L14*_xlfn.XLOOKUP(NPV_Output!H$8,_xlfn.ANCHORARRAY( ControlPanel!$B$10),_xlfn.ANCHORARRAY( ControlPanel!$C$10))*Assumptions!$O$12} -> 871821.11 | I17: {='Carbon_Emission&Exposure'!M14*_xlfn.XLOOKUP(NPV_Output!I$8,_xlfn.ANCHORARRAY( ControlPanel!$B$10),_xlfn.ANCHORARRAY( ControlPanel!$C$10))*Assumptions!$O$12} -> 932361.24 | J17: {='Carbon_Emission&Exposure'!N14*_xlfn.XLOOKUP(NPV_Output!J$8,_xlfn.ANCHORARRAY( ControlPanel!$B$10),_xlfn.ANCHORARRAY( ControlPanel!$C$10))*Assumptions!$O$12} -> 993799.06 | ... L17: {='Carbon_Emission&Exposure'!P14*_xlfn.XLOOKUP(NPV_Output!L$8,_xlfn.ANCHORARRAY( ControlPanel!$B$10),_xlfn.ANCHORARRAY( ControlPanel!$C$10))*Assumptions!$O$12} -> 1121711 | N17: =SUMPRODUCT(C17:L17,DCF!R14:AA14) -> 6549154
B18: GSK plc | C18: {='Carbon_Emission&Exposure'!G15*_xlfn.XLOOKUP(NPV_Output!C$8,_xlfn.ANCHORARRAY( ControlPanel!$B$10),_xlfn.ANCHORARRAY( ControlPanel!$C$10))*Assumptions!$O$12} -> 2633415.3 | D18: {='Carbon_Emission&Exposure'!H15*_xlfn.XLOOKUP(NPV_Output!D$8,_xlfn.ANCHORARRAY( ControlPanel!$B$10),_xlfn.ANCHORARRAY( ControlPanel!$C$10))*Assumptions!$O$12} -> 3215981.3 | E18: {='Carbon_Emission&Exposure'!I15*_xlfn.XLOOKUP(NPV_Output!E$8,_xlfn.ANCHORARRAY( ControlPanel!$B$10),_xlfn.ANCHORARRAY( ControlPanel!$C$10))*Assumptions!$O$12} -> 3554947 | F18: {='Carbon_Emission&Exposure'!J15*_xlfn.XLOOKUP(NPV_Output!F$8,_xlfn.ANCHORARRAY( ControlPanel!$B$10),_xlfn.ANCHORARRAY( ControlPanel!$C$10))*Assumptions!$O$12} -> 3872003.1 | G18: {='Carbon_Emission&Exposure'!K15*_xlfn.XLOOKUP(NPV_Output!G$8,_xlfn.ANCHORARRAY( ControlPanel!$B$10),_xlfn.ANCHORARRAY( ControlPanel!$C$10))*Assumptions!$O$12} -> 4175422.7 | H18: {='Carbon_Emission&Exposure'!L15*_xlfn.XLOOKUP(NPV_Output!H$8,_xlfn.ANCHORARRAY( ControlPanel!$B$10),_xlfn.ANCHORARRAY( ControlPanel!$C$10))*Assumptions!$O$12} -> 4481028.7 | I18: {='Carbon_Emission&Exposure'!M15*_xlfn.XLOOKUP(NPV_Output!I$8,_xlfn.ANCHORARRAY( ControlPanel!$B$10),_xlfn.ANCHORARRAY( ControlPanel!$C$10))*Assumptions!$O$12} -> 4792195.8 | J18: {='Carbon_Emission&Exposure'!N15*_xlfn.XLOOKUP(NPV_Output!J$8,_xlfn.ANCHORARRAY( ControlPanel!$B$10),_xlfn.ANCHORARRAY( ControlPanel!$C$10))*Assumptions!$O$12} -> 5107976.9 | ... L18: {='Carbon_Emission&Exposure'!P15*_xlfn.XLOOKUP(NPV_Output!L$8,_xlfn.ANCHORARRAY( ControlPanel!$B$10),_xlfn.ANCHORARRAY( ControlPanel!$C$10))*Assumptions!$O$12} -> 5765425.1 | N18: =SUMPRODUCT(C18:L18,DCF!R15:AA15) -> 33661924
B19: BioNTech SE | C19: {='Carbon_Emission&Exposure'!G16*_xlfn.XLOOKUP(NPV_Output!C$8,_xlfn.ANCHORARRAY( ControlPanel!$B$10),_xlfn.ANCHORARRAY( ControlPanel!$C$10))*Assumptions!$O$12} -> 132098.28 | D19: {='Carbon_Emission&Exposure'!H16*_xlfn.XLOOKUP(NPV_Output!D$8,_xlfn.ANCHORARRAY( ControlPanel!$B$10),_xlfn.ANCHORARRAY( ControlPanel!$C$10))*Assumptions!$O$12} -> 164664.6 | E19: {='Carbon_Emission&Exposure'!I16*_xlfn.XLOOKUP(NPV_Output!E$8,_xlfn.ANCHORARRAY( ControlPanel!$B$10),_xlfn.ANCHORARRAY( ControlPanel!$C$10))*Assumptions!$O$12} -> 185792.75 | F19: {='Carbon_Emission&Exposure'!J16*_xlfn.XLOOKUP(NPV_Output!F$8,_xlfn.ANCHORARRAY( ControlPanel!$B$10),_xlfn.ANCHORARRAY( ControlPanel!$C$10))*Assumptions!$O$12} -> 206557.16 | G19: {='Carbon_Emission&Exposure'!K16*_xlfn.XLOOKUP(NPV_Output!G$8,_xlfn.ANCHORARRAY( ControlPanel!$B$10),_xlfn.ANCHORARRAY( ControlPanel!$C$10))*Assumptions!$O$12} -> 227359.93 | H19: {='Carbon_Emission&Exposure'!L16*_xlfn.XLOOKUP(NPV_Output!H$8,_xlfn.ANCHORARRAY( ControlPanel!$B$10),_xlfn.ANCHORARRAY( ControlPanel!$C$10))*Assumptions!$O$12} -> 249057.78 | I19: {='Carbon_Emission&Exposure'!M16*_xlfn.XLOOKUP(NPV_Output!I$8,_xlfn.ANCHORARRAY( ControlPanel!$B$10),_xlfn.ANCHORARRAY( ControlPanel!$C$10))*Assumptions!$O$12} -> 271872.87 | J19: {='Carbon_Emission&Exposure'!N16*_xlfn.XLOOKUP(NPV_Output!J$8,_xlfn.ANCHORARRAY( ControlPanel!$B$10),_xlfn.ANCHORARRAY( ControlPanel!$C$10))*Assumptions!$O$12} -> 295793.86 | ... L19: {='Carbon_Emission&Exposure'!P16*_xlfn.XLOOKUP(NPV_Output!L$8,_xlfn.ANCHORARRAY( ControlPanel!$B$10),_xlfn.ANCHORARRAY( ControlPanel!$C$10))*Assumptions!$O$12} -> 347847.91 | N19: =SUMPRODUCT(C19:L19,DCF!R16:AA16) -> 1327494.4
B20: Pfizer | C20: {='Carbon_Emission&Exposure'!G17*_xlfn.XLOOKUP(NPV_Output!C$8,_xlfn.ANCHORARRAY( ControlPanel!$B$10),_xlfn.ANCHORARRAY( ControlPanel!$C$10))*Assumptions!$O$12} -> 6906780.2 | D20: {='Carbon_Emission&Exposure'!H17*_xlfn.XLOOKUP(NPV_Output!D$8,_xlfn.ANCHORARRAY( ControlPanel!$B$10),_xlfn.ANCHORARRAY( ControlPanel!$C$10))*Assumptions!$O$12} -> 8609515.6 | E20: {='Carbon_Emission&Exposure'!I17*_xlfn.XLOOKUP(NPV_Output!E$8,_xlfn.ANCHORARRAY( ControlPanel!$B$10),_xlfn.ANCHORARRAY( ControlPanel!$C$10))*Assumptions!$O$12} -> 9714204.7 | F20: {='Carbon_Emission&Exposure'!J17*_xlfn.XLOOKUP(NPV_Output!F$8,_xlfn.ANCHORARRAY( ControlPanel!$B$10),_xlfn.ANCHORARRAY( ControlPanel!$C$10))*Assumptions!$O$12} -> 10799875 | G20: {='Carbon_Emission&Exposure'!K17*_xlfn.XLOOKUP(NPV_Output!G$8,_xlfn.ANCHORARRAY( ControlPanel!$B$10),_xlfn.ANCHORARRAY( ControlPanel!$C$10))*Assumptions!$O$12} -> 11887551 | H20: {='Carbon_Emission&Exposure'!L17*_xlfn.XLOOKUP(NPV_Output!H$8,_xlfn.ANCHORARRAY( ControlPanel!$B$10),_xlfn.ANCHORARRAY( ControlPanel!$C$10))*Assumptions!$O$12} -> 13022027 | I20: {='Carbon_Emission&Exposure'!M17*_xlfn.XLOOKUP(NPV_Output!I$8,_xlfn.ANCHORARRAY( ControlPanel!$B$10),_xlfn.ANCHORARRAY( ControlPanel!$C$10))*Assumptions!$O$12} -> 14214918 | J20: {='Carbon_Emission&Exposure'!N17*_xlfn.XLOOKUP(NPV_Output!J$8,_xlfn.ANCHORARRAY( ControlPanel!$B$10),_xlfn.ANCHORARRAY( ControlPanel!$C$10))*Assumptions!$O$12} -> 15465631 | ... L20: {='Carbon_Emission&Exposure'!P17*_xlfn.XLOOKUP(NPV_Output!L$8,_xlfn.ANCHORARRAY( ControlPanel!$B$10),_xlfn.ANCHORARRAY( ControlPanel!$C$10))*Assumptions!$O$12} -> 18187285 | N20: =SUMPRODUCT(C20:L20,DCF!R17:AA17) -> 92278235
B21: Johnson & Johnson | C21: {='Carbon_Emission&Exposure'!G18*_xlfn.XLOOKUP(NPV_Output!C$8,_xlfn.ANCHORARRAY( ControlPanel!$B$10),_xlfn.ANCHORARRAY( ControlPanel!$C$10))*Assumptions!$O$12} -> 9014196.7 | D21: {='Carbon_Emission&Exposure'!H18*_xlfn.XLOOKUP(NPV_Output!D$8,_xlfn.ANCHORARRAY( ControlPanel!$B$10),_xlfn.ANCHORARRAY( ControlPanel!$C$10))*Assumptions!$O$12} -> 11236476 | E21: {='Carbon_Emission&Exposure'!I18*_xlfn.XLOOKUP(NPV_Output!E$8,_xlfn.ANCHORARRAY( ControlPanel!$B$10),_xlfn.ANCHORARRAY( ControlPanel!$C$10))*Assumptions!$O$12} -> 12678231 | F21: {='Carbon_Emission&Exposure'!J18*_xlfn.XLOOKUP(NPV_Output!F$8,_xlfn.ANCHORARRAY( ControlPanel!$B$10),_xlfn.ANCHORARRAY( ControlPanel!$C$10))*Assumptions!$O$12} -> 14095164 | G21: {='Carbon_Emission&Exposure'!K18*_xlfn.XLOOKUP(NPV_Output!G$8,_xlfn.ANCHORARRAY( ControlPanel!$B$10),_xlfn.ANCHORARRAY( ControlPanel!$C$10))*Assumptions!$O$12} -> 15514715 | H21: {='Carbon_Emission&Exposure'!L18*_xlfn.XLOOKUP(NPV_Output!H$8,_xlfn.ANCHORARRAY( ControlPanel!$B$10),_xlfn.ANCHORARRAY( ControlPanel!$C$10))*Assumptions!$O$12} -> 16995345 | I21: {='Carbon_Emission&Exposure'!M18*_xlfn.XLOOKUP(NPV_Output!I$8,_xlfn.ANCHORARRAY( ControlPanel!$B$10),_xlfn.ANCHORARRAY( ControlPanel!$C$10))*Assumptions!$O$12} -> 18552214 | J21: {='Carbon_Emission&Exposure'!N18*_xlfn.XLOOKUP(NPV_Output!J$8,_xlfn.ANCHORARRAY( ControlPanel!$B$10),_xlfn.ANCHORARRAY( ControlPanel!$C$10))*Assumptions!$O$12} -> 20184548 | ... L21: {='Carbon_Emission&Exposure'!P18*_xlfn.XLOOKUP(NPV_Output!L$8,_xlfn.ANCHORARRAY( ControlPanel!$B$10),_xlfn.ANCHORARRAY( ControlPanel!$C$10))*Assumptions!$O$12} -> 23736641 | N21: =SUMPRODUCT(C21:L21,DCF!R18:AA18) -> 1.2423027e+08
B24: Transport
B27: PostNL | C27: {='Carbon_Emission&Exposure'!G24*_xlfn.XLOOKUP(NPV_Output!C$8,_xlfn.ANCHORARRAY( ControlPanel!$B$10),_xlfn.ANCHORARRAY( ControlPanel!$C$10))*Assumptions!$O$18} -> 271374.44 | D27: {='Carbon_Emission&Exposure'!H24*_xlfn.XLOOKUP(NPV_Output!D$8,_xlfn.ANCHORARRAY( ControlPanel!$B$10),_xlfn.ANCHORARRAY( ControlPanel!$C$10))*Assumptions!$O$18} -> 335068.17 | E27: {='Carbon_Emission&Exposure'!I24*_xlfn.XLOOKUP(NPV_Output!E$8,_xlfn.ANCHORARRAY( ControlPanel!$B$10),_xlfn.ANCHORARRAY( ControlPanel!$C$10))*Assumptions!$O$18} -> 374475.02 | F27: {='Carbon_Emission&Exposure'!J24*_xlfn.XLOOKUP(NPV_Output!F$8,_xlfn.ANCHORARRAY( ControlPanel!$B$10),_xlfn.ANCHORARRAY( ControlPanel!$C$10))*Assumptions!$O$18} -> 412378 | G27: {='Carbon_Emission&Exposure'!K24*_xlfn.XLOOKUP(NPV_Output!G$8,_xlfn.ANCHORARRAY( ControlPanel!$B$10),_xlfn.ANCHORARRAY( ControlPanel!$C$10))*Assumptions!$O$18} -> 449604.14 | H27: {='Carbon_Emission&Exposure'!L24*_xlfn.XLOOKUP(NPV_Output!H$8,_xlfn.ANCHORARRAY( ControlPanel!$B$10),_xlfn.ANCHORARRAY( ControlPanel!$C$10))*Assumptions!$O$18} -> 487840.27 | I27: {='Carbon_Emission&Exposure'!M24*_xlfn.XLOOKUP(NPV_Output!I$8,_xlfn.ANCHORARRAY( ControlPanel!$B$10),_xlfn.ANCHORARRAY( ControlPanel!$C$10))*Assumptions!$O$18} -> 527478.24 | J27: {='Carbon_Emission&Exposure'!N24*_xlfn.XLOOKUP(NPV_Output!J$8,_xlfn.ANCHORARRAY( ControlPanel!$B$10),_xlfn.ANCHORARRAY( ControlPanel!$C$10))*Assumptions!$O$18} -> 568445.7 | ... L27: {='Carbon_Emission&Exposure'!P24*_xlfn.XLOOKUP(NPV_Output!L$8,_xlfn.ANCHORARRAY( ControlPanel!$B$10),_xlfn.ANCHORARRAY( ControlPanel!$C$10))*Assumptions!$O$18} -> 655860.58 | N27: =SUMPRODUCT(C27:L27,DCF!R24:AA24) -> 3175216.5
B28: DHL Group | C28: {='Carbon_Emission&Exposure'!G25*_xlfn.XLOOKUP(NPV_Output!C$8,_xlfn.ANCHORARRAY( ControlPanel!$B$10),_xlfn.ANCHORARRAY( ControlPanel!$C$10))*Assumptions!$O$18} -> 17205139 | D28: {='Carbon_Emission&Exposure'!H25*_xlfn.XLOOKUP(NPV_Output!D$8,_xlfn.ANCHORARRAY( ControlPanel!$B$10),_xlfn.ANCHORARRAY( ControlPanel!$C$10))*Assumptions!$O$18} -> 21243322 | E28: {='Carbon_Emission&Exposure'!I25*_xlfn.XLOOKUP(NPV_Output!E$8,_xlfn.ANCHORARRAY( ControlPanel!$B$10),_xlfn.ANCHORARRAY( ControlPanel!$C$10))*Assumptions!$O$18} -> 23741716 | F28: {='Carbon_Emission&Exposure'!J25*_xlfn.XLOOKUP(NPV_Output!F$8,_xlfn.ANCHORARRAY( ControlPanel!$B$10),_xlfn.ANCHORARRAY( ControlPanel!$C$10))*Assumptions!$O$18} -> 26144765 | G28: {='Carbon_Emission&Exposure'!K25*_xlfn.XLOOKUP(NPV_Output!G$8,_xlfn.ANCHORARRAY( ControlPanel!$B$10),_xlfn.ANCHORARRAY( ControlPanel!$C$10))*Assumptions!$O$18} -> 28504903 | H28: {='Carbon_Emission&Exposure'!L25*_xlfn.XLOOKUP(NPV_Output!H$8,_xlfn.ANCHORARRAY( ControlPanel!$B$10),_xlfn.ANCHORARRAY( ControlPanel!$C$10))*Assumptions!$O$18} -> 30929073 | I28: {='Carbon_Emission&Exposure'!M25*_xlfn.XLOOKUP(NPV_Output!I$8,_xlfn.ANCHORARRAY( ControlPanel!$B$10),_xlfn.ANCHORARRAY( ControlPanel!$C$10))*Assumptions!$O$18} -> 33442121 | J28: {='Carbon_Emission&Exposure'!N25*_xlfn.XLOOKUP(NPV_Output!J$8,_xlfn.ANCHORARRAY( ControlPanel!$B$10),_xlfn.ANCHORARRAY( ControlPanel!$C$10))*Assumptions!$O$18} -> 36039458 | ... L28: {='Carbon_Emission&Exposure'!P25*_xlfn.XLOOKUP(NPV_Output!L$8,_xlfn.ANCHORARRAY( ControlPanel!$B$10),_xlfn.ANCHORARRAY( ControlPanel!$C$10))*Assumptions!$O$18} -> 41581561 | N28: =SUMPRODUCT(C28:L28,DCF!R25:AA25) -> 1.769724e+08
B29: XPO Logistics | C29: {='Carbon_Emission&Exposure'!G26*_xlfn.XLOOKUP(NPV_Output!C$8,_xlfn.ANCHORARRAY( ControlPanel!$B$10),_xlfn.ANCHORARRAY( ControlPanel!$C$10))*Assumptions!$O$18} -> 2756691.8 | D29: {='Carbon_Emission&Exposure'!H26*_xlfn.XLOOKUP(NPV_Output!D$8,_xlfn.ANCHORARRAY( ControlPanel!$B$10),_xlfn.ANCHORARRAY( ControlPanel!$C$10))*Assumptions!$O$18} -> 3474252.4 | E29: {='Carbon_Emission&Exposure'!I26*_xlfn.XLOOKUP(NPV_Output!E$8,_xlfn.ANCHORARRAY( ControlPanel!$B$10),_xlfn.ANCHORARRAY( ControlPanel!$C$10))*Assumptions!$O$18} -> 3963327.6 | F29: {='Carbon_Emission&Exposure'!J26*_xlfn.XLOOKUP(NPV_Output!F$8,_xlfn.ANCHORARRAY( ControlPanel!$B$10),_xlfn.ANCHORARRAY( ControlPanel!$C$10))*Assumptions!$O$18} -> 4454936.6 | G29: {='Carbon_Emission&Exposure'!K26*_xlfn.XLOOKUP(NPV_Output!G$8,_xlfn.ANCHORARRAY( ControlPanel!$B$10),_xlfn.ANCHORARRAY( ControlPanel!$C$10))*Assumptions!$O$18} -> 4957757.3 | H29: {='Carbon_Emission&Exposure'!L26*_xlfn.XLOOKUP(NPV_Output!H$8,_xlfn.ANCHORARRAY( ControlPanel!$B$10),_xlfn.ANCHORARRAY( ControlPanel!$C$10))*Assumptions!$O$18} -> 5490874.6 | I29: {='Carbon_Emission&Exposure'!M26*_xlfn.XLOOKUP(NPV_Output!I$8,_xlfn.ANCHORARRAY( ControlPanel!$B$10),_xlfn.ANCHORARRAY( ControlPanel!$C$10))*Assumptions!$O$18} -> 6060065.8 | J29: {='Carbon_Emission&Exposure'!N26*_xlfn.XLOOKUP(NPV_Output!J$8,_xlfn.ANCHORARRAY( ControlPanel!$B$10),_xlfn.ANCHORARRAY( ControlPanel!$C$10))*Assumptions!$O$18} -> 6666082.6 | ... L29: {='Carbon_Emission&Exposure'!P26*_xlfn.XLOOKUP(NPV_Output!L$8,_xlfn.ANCHORARRAY( ControlPanel!$B$10),_xlfn.ANCHORARRAY( ControlPanel!$C$10))*Assumptions!$O$18} -> 8013293.8 | N29: =SUMPRODUCT(C29:L29,DCF!R26:AA26) -> 26197003
